<?xml version="1.0" ?>
<robot name="UR5ARM" xmlns:xacro="http://www.ros.org/wiki/xacro">

<xacro:include filename="$(find UR5ARM_description)/urdf/materials.xacro" />
<xacro:include filename="$(find UR5ARM_description)/urdf/UR5ARM.trans" />
<xacro:include filename="$(find UR5ARM_description)/urdf/UR5ARM.gazebo" />
<xacro:include filename="(find UR5ARM_description)/urdf/gazebo_control.xacro"

<link name="base_link">
  <inertial>
    <origin xyz="0.050000000000039437 0.05000000000000002 0.005" rpy="0 0 0"/>
    <mass value="20.1040581864031684"/>
    <inertia ixx="0.001627" iyy="0.001627" izz="0.003235" ixy="0.0" iyz="0.0" ixz="0.0"/>
  </inertial>
  <visual>
    <origin xyz="0 0 0" rpy="0 0 0"/>
    <geometry>
      <mesh filename="file://$(find UR5ARM_description)/meshes/base_link.stl" scale="0.001 0.001 0.001"/>
    </geometry>
    <material name="white"/>
  </visual>
  <collision>
    <origin xyz="0 0 0" rpy="0 0 0"/>
    <geometry>
      <mesh filename="file://$(find UR5ARM_description)/meshes/base_link.stl" scale="0.001 0.001 0.001"/>
    </geometry>
  </collision>
</link>

<link name="limb1_1">
  <inertial>
    <origin xyz="-0.009004688316953849 -7.917650965416634e-09 0.049239803683814656" rpy="0 0 0"/>
    <mass value="17.055909957363043"/>
    <inertia ixx="0.009247" iyy="0.012449" izz="0.011335" ixy="-0.0" iyz="0.0" ixz="4.8e-05"/>
  </inertial>
  <visual>
    <origin xyz="-0.05 -0.05 -0.01" rpy="0 0 0"/>
    <geometry>
      <mesh filename="file://$(find UR5ARM_description)/meshes/limb1_1.stl" scale="0.001 0.001 0.001"/>
    </geometry>
    <material name="green"/>
  </visual>
  <collision>
    <origin xyz="-0.05 -0.05 -0.01" rpy="0 0 0"/>
    <geometry>
      <mesh filename="file://$(find UR5ARM_description)/meshes/limb1_1.stl" scale="0.001 0.001 0.001"/>
    </geometry>
  </collision>
</link>

<link name="limb2_1">
  <inertial>
    <origin xyz="-0.05025336509992895 -0.0004071089383043819 0.16747864943323507" rpy="0 0 0"/>
    <mass value="11.481378845351724"/>
    <inertia ixx="0.217772" iyy="0.221035" izz="0.009225" ixy="3e-06" iyz="0.000816" ixz="-0.000825"/>
  </inertial>
  <visual>
    <origin xyz="0.03 -0.05 -0.06" rpy="0 0 0"/>
    <geometry>
      <mesh filename="file://$(find UR5ARM_description)/meshes/limb2_1.stl" scale="0.001 0.001 0.001"/>
    </geometry>
    <material name="blue"/>
  </visual>
  <collision>
    <origin xyz="0.03 -0.05 -0.06" rpy="0 0 0"/>
    <geometry>
      <mesh filename="file://$(find UR5ARM_description)/meshes/limb2_1.stl" scale="0.001 0.001 0.001"/>
    </geometry>
  </collision>
</link>

<link name="limb3_1">
  <inertial>
    <origin xyz="0.046538937761709205 -0.0010362412450358807 0.14608818175975624" rpy="0 0 0"/>
    <mass value="9.288309760814267"/>
    <inertia ixx="0.144854" iyy="0.148475" izz="0.008428" ixy="-1e-05" iyz="0.00061" ixz="-0.000133"/>
  </inertial>
  <visual>
    <origin xyz="0.03 -0.048308 -0.399856" rpy="0 0 0"/>
    <geometry>
      <mesh filename="file://$(find UR5ARM_description)/meshes/limb3_1.stl" scale="0.001 0.001 0.001"/>
    </geometry>
    <material name="red"/>
  </visual>
  <collision>
    <origin xyz="0.03 -0.048308 -0.399856" rpy="0 0 0"/>
    <geometry>
      <mesh filename="file://$(find UR5ARM_description)/meshes/limb3_1.stl" scale="0.001 0.001 0.001"/>
    </geometry>
  </collision>
</link>

<link name="limb4_1">
  <inertial>
    <origin xyz="-0.048711945428796866 0.0006132964252048775 0.05989971043637188" rpy="0 0 0"/>
    <mass value="8.67005895677848"/>
    <inertia ixx="0.020904" iyy="0.025876" izz="0.012819" ixy="2.1e-05" iyz="-5.4e-05" ixz="0.003125"/>
  </inertial>
  <visual>
    <origin xyz="0.035 -0.046775 -0.684692" rpy="0 0 0"/>
    <geometry>
      <mesh filename="file://$(find UR5ARM_description)/meshes/limb4_1.stl" scale="0.001 0.001 0.001"/>
    </geometry>
    <material name="yellow"/>
  </visual>
  <collision>
    <origin xyz="0.035 -0.046775 -0.684692" rpy="0 0 0"/>
    <geometry>
      <mesh filename="file://$(find UR5ARM_description)/meshes/limb4_1.stl" scale="0.001 0.001 0.001"/>
    </geometry>
  </collision>
</link>

<link name="end_effector_1">
  <inertial>
    <origin xyz="-0.013724875834761147 -5.113964807179627e-15 1.1102230246251565e-16" rpy="0 0 0"/>
    <mass value="1.3403817613935933"/>
    <inertia ixx="0.001403" iyy="0.000792" izz="0.000792" ixy="-0.0" iyz="0.0" ixz="0.0"/>
  </inertial>
  <visual>
    <origin xyz="0.15 -0.0475 -0.77" rpy="0 0 0"/>
    <geometry>
      <mesh filename="file://$(find UR5ARM_description)/meshes/end_effector_1.stl" scale="0.001 0.001 0.001"/>
    </geometry>
    <material name="white"/>
  </visual>
  <collision>
    <origin xyz="0.15 -0.0475 -0.77" rpy="0 0 0"/>
    <geometry>
      <mesh filename="file://$(find UR5ARM_description)/meshes/end_effector_1.stl" scale="0.001 0.001 0.001"/>
    </geometry>
  </collision>
</link>

<joint name="limb1_to_base_link" type="continuous">
  <origin xyz="0.05 0.05 0.01" rpy="0 0 0"/>
  <parent link="base_link"/>
  <child link="limb1_1"/>
  <axis xyz="0.0 0.0 1.0"/>
</joint>

<joint name="limb2_to_limb1" type="continuous">
  <origin xyz="-0.08 0.0 0.05" rpy="0 0 0"/>
  <parent link="limb1_1"/>
  <child link="limb2_1"/>
  <axis xyz="-1.0 0.0 0.0"/>
</joint>

<joint name="limb3_to_limb2" type="continuous">
  <origin xyz="0.0 -0.001692 0.339856" rpy="0 0 0"/>
  <parent link="limb2_1"/>
  <child link="limb3_1"/>
  <axis xyz="1.0 0.0 0.0"/>
</joint>

<joint name="limb4_to_limb3" type="continuous">
  <origin xyz="-0.005 -0.001533 0.284836" rpy="0 0 0"/>
  <parent link="limb3_1"/>
  <child link="limb4_1"/>
  <axis xyz="-1.0 0.0 0.0"/>
</joint>

<joint name="end_effector_to_limb4" type="continuous">
  <origin xyz="-0.115 0.000725 0.085308" rpy="0 0 0"/>
  <parent link="limb4_1"/>
  <child link="end_effector_1"/>
  <axis xyz="-1.0 0.0 0.0"/>
</joint>

<ros2_control name="GazeboSystem" type="system">
  <hardware>

  </hardware>


</ros2_control>

</robot>
